2021-06-14T15:53:27|CRITICAL|root|Unhandled exception:Traceback (most recent call last):
  File "C:\LabPrograms\Python\ScopeFoundryProjects\PROCHIP microscope\Flir_ScopeFoundry\camera_measure.py", line 122, in run
    self.image_gen.camera.acq_start()
AttributeError: 'FlirHW' object has no attribute 'camera'

During handling of the above exception, another exception occurred:

Traceback (most recent call last):
  File "C:\Users\LAB\Anaconda3\envs\scopefoundry\lib\site-packages\ScopeFoundry\measurement.py", line 25, in run
    self.measurement._thread_run()
  File "C:\Users\LAB\Anaconda3\envs\scopefoundry\lib\site-packages\ScopeFoundry\measurement.py", line 179, in _thread_run
    self.run()
  File "C:\LabPrograms\Python\ScopeFoundryProjects\PROCHIP microscope\Flir_ScopeFoundry\camera_measure.py", line 163, in run
    self.image_gen.camera.acq_stop()
AttributeError: 'FlirHW' object has no attribute 'camera'

